<sdf version='1.10'>
  <world name='default'>
    <plugin name='gz::sim::systems::Physics' filename='gz-sim-physics-system'/>
    <plugin name='gz::sim::systems::UserCommands' filename='gz-sim-user-commands-system'/>
    <plugin name='gz::sim::systems::SceneBroadcaster' filename='gz-sim-scene-broadcaster-system'/>
    <plugin name='gz::sim::systems::Sensors' filename='gz-sim-sensors-system'>
      <render_engine>ogre2</render_engine>
    </plugin>
    <plugin name='gz::sim::systems::Imu' filename='gz-sim-imu-system'/>
    <scene>
      <shadows>false</shadows>
      <ambient>0.400000006 0.400000006 0.400000006 1</ambient>
      <background>0.699999988 0.699999988 0.699999988 1</background>
    </scene>
    <gui>
      <camera name='user_camera'>
        <pose>0 0 0 0 0 0</pose>
      </camera>
    </gui>
    <physics type='ode'>
      <real_time_update_rate>1000</real_time_update_rate>
      <max_step_size>0.001</max_step_size>
      <real_time_factor>1</real_time_factor>
    </physics>
    <gravity>0 0 -9.8000000000000007</gravity>
    <magnetic_field>5.5644999999999998e-06 2.2875799999999999e-05 -4.2388400000000002e-05</magnetic_field>
    <atmosphere type='adiabatic'/>
    <model name='ground_plane'>
      <static>true</static>
      <link name='ground'>
        <visual name='visual'>
          <geometry>
            <plane>
              <size>2 2</size>
              <normal>0 0 1</normal>
            </plane>
          </geometry>
          <material>
            <ambient>0 0 1 0.5</ambient>
            <diffuse>0 0 1 0.5</diffuse>
            <specular>0 0 1 0.5</specular>
          </material>
        </visual>
        <collision name='collision'>
          <geometry>
            <plane>
              <size>2 2</size>
              <normal>0 0 1</normal>
            </plane>
          </geometry>
          <surface>
            <friction>
              <ode>
                <mu>1.10000000000000001</mu>
                <mu2>0</mu2>
              </ode>
            </friction>
            <bounce/>
            <contact/>
          </surface>
        </collision>
        <pose>0 0 0 0 0 0</pose>
        <inertial>
          <pose>0 0 0 0 0 0</pose>
          <mass>1</mass>
          <inertia>
            <ixx>1</ixx>
            <ixy>0</ixy>
            <ixz>0</ixz>
            <iyy>1</iyy>
            <iyz>0</iyz>
            <izz>1</izz>
          </inertia>
        </inertial>
        <enable_wind>false</enable_wind>
      </link>
      <pose>0 0 0 0 0 0</pose>
      <self_collide>false</self_collide>
    </model>
    <model name='robot'>
      <joint name='slider_joint' type='prismatic'>
        <pose>0 0 0 0 0 0</pose>
        <parent>world</parent>
        <child>base_link</child>
        <axis>
          <xyz>0 0 1</xyz>
          <limit>
            <lower>-10</lower>
            <upper>10</upper>
            <effort>0</effort>
            <velocity>100</velocity>
            <stiffness>100000000</stiffness>
            <dissipation>1</dissipation>
          </limit>
          <dynamics>
            <spring_reference>0</spring_reference>
            <spring_stiffness>0</spring_stiffness>
            <damping>0</damping>
            <friction>0.10000000000000001</friction>
          </dynamics>
        </axis>
      </joint>
      <link name='base_link'>
        <pose>0 0 1 0 0 0</pose>
        <inertial>
          <pose>0 0 0 0 0 0</pose>
          <mass>0.01</mass>
          <inertia>
            <ixx>0.01</ixx>
            <ixy>0</ixy>
            <ixz>0</ixz>
            <iyy>0.01</iyy>
            <iyz>0</iyz>
            <izz>0.01</izz>
          </inertia>
        </inertial>
        <sensor name='imu' type='imu'>
          <pose>0 0 0 0 0 0</pose>
          <topic>/model/robot/sensors/imu</topic>
          <update_rate>100</update_rate>
          <enable_metrics>false</enable_metrics>
          <imu>
            <orientation_reference_frame>
              <localization>ENU</localization>
              <custom_rpy>0 0 0</custom_rpy>
              <grav_dir_x>1 0 0</grav_dir_x>
            </orientation_reference_frame>
            <angular_velocity>
              <x>
                <noise type='none'>
                  <mean>0</mean>
                  <stddev>0</stddev>
                  <bias_mean>0</bias_mean>
                  <bias_stddev>0</bias_stddev>
                  <dynamic_bias_stddev>0</dynamic_bias_stddev>
                  <dynamic_bias_correlation_time>0</dynamic_bias_correlation_time>
                  <precision>0</precision>
                </noise>
              </x>
              <y>
                <noise type='none'>
                  <mean>0</mean>
                  <stddev>0</stddev>
                  <bias_mean>0</bias_mean>
                  <bias_stddev>0</bias_stddev>
                  <dynamic_bias_stddev>0</dynamic_bias_stddev>
                  <dynamic_bias_correlation_time>0</dynamic_bias_correlation_time>
                  <precision>0</precision>
                </noise>
              </y>
              <z>
                <noise type='none'>
                  <mean>0</mean>
                  <stddev>0</stddev>
                  <bias_mean>0</bias_mean>
                  <bias_stddev>0</bias_stddev>
                  <dynamic_bias_stddev>0</dynamic_bias_stddev>
                  <dynamic_bias_correlation_time>0</dynamic_bias_correlation_time>
                  <precision>0</precision>
                </noise>
              </z>
            </angular_velocity>
            <linear_acceleration>
              <x>
                <noise type='none'>
                  <mean>0</mean>
                  <stddev>0</stddev>
                  <bias_mean>0</bias_mean>
                  <bias_stddev>0</bias_stddev>
                  <dynamic_bias_stddev>0</dynamic_bias_stddev>
                  <dynamic_bias_correlation_time>0</dynamic_bias_correlation_time>
                  <precision>0</precision>
                </noise>
              </x>
              <y>
                <noise type='none'>
                  <mean>0</mean>
                  <stddev>0</stddev>
                  <bias_mean>0</bias_mean>
                  <bias_stddev>0</bias_stddev>
                  <dynamic_bias_stddev>0</dynamic_bias_stddev>
                  <dynamic_bias_correlation_time>0</dynamic_bias_correlation_time>
                  <precision>0</precision>
                </noise>
              </y>
              <z>
                <noise type='none'>
                  <mean>0</mean>
                  <stddev>0</stddev>
                  <bias_mean>0</bias_mean>
                  <bias_stddev>0</bias_stddev>
                  <dynamic_bias_stddev>0</dynamic_bias_stddev>
                  <dynamic_bias_correlation_time>0</dynamic_bias_correlation_time>
                  <precision>0</precision>
                </noise>
              </z>
            </linear_acceleration>
            <enable_orientation>true</enable_orientation>
          </imu>
        </sensor>
        <enable_wind>false</enable_wind>
      </link>
      <joint name='hip_joint' type='revolute'>
        <pose>0 0 0 0 0 0</pose>
        <parent>base_link</parent>
        <child>hip_link</child>
        <axis>
          <xyz>0 0 1</xyz>
          <limit>
            <lower>-3.1415926535897931</lower>
            <upper>3.1415926535897931</upper>
            <effort>10.5</effort>
            <velocity>62.899999999999999</velocity>
            <stiffness>100000000</stiffness>
            <dissipation>1</dissipation>
          </limit>
          <dynamics>
            <spring_reference>0</spring_reference>
            <spring_stiffness>0</spring_stiffness>
            <damping>0.10000000000000001</damping>
            <friction>0.10000000000000001</friction>
          </dynamics>
        </axis>
      </joint>
      <link name='hip_link'>
        <pose>0 0 1 1.5707963267948946 -1.5707963267948966 0</pose>
        <inertial>
          <pose>0 0 0 0 0 0</pose>
          <mass>1</mass>
          <inertia>
            <ixx>0.01</ixx>
            <ixy>0</ixy>
            <ixz>0</ixz>
            <iyy>0.01</iyy>
            <iyz>0</iyz>
            <izz>0.01</izz>
          </inertia>
        </inertial>
        <collision name='hip_link_collision'>
          <pose>-0.14999999999999999 0 0 0 0 0</pose>
          <geometry>
            <box>
              <size>0.29999999999999999 0.050000000000000003 0.02</size>
            </box>
          </geometry>
          <surface>
            <friction>
              <ode/>
            </friction>
            <bounce/>
            <contact/>
          </surface>
        </collision>
        <visual name='hip_link_visual'>
          <pose>-0.14999999999999999 0 0 0 0 0</pose>
          <geometry>
            <box>
              <size>0.29999999999999999 0.050000000000000003 0.02</size>
            </box>
          </geometry>
          <material>
            <diffuse>0 0 1 1</diffuse>
            <ambient>0 0 1 1</ambient>
          </material>
        </visual>
        <enable_wind>false</enable_wind>
      </link>
      <joint name='knee_joint' type='revolute'>
        <pose>0 -2.7755575615628914e-17 5.5511151231257827e-17 0 0 0</pose>
        <parent>hip_link</parent>
        <child>knee_link</child>
        <axis>
          <xyz>0 0 1</xyz>
          <limit>
            <lower>-3.1415926535897931</lower>
            <upper>3.1415926535897931</upper>
            <effort>10.5</effort>
            <velocity>62.899999999999999</velocity>
            <stiffness>100000000</stiffness>
            <dissipation>1</dissipation>
          </limit>
          <dynamics>
            <spring_reference>0</spring_reference>
            <spring_stiffness>0</spring_stiffness>
            <damping>0.10000000000000001</damping>
            <friction>0.10000000000000001</friction>
          </dynamics>
        </axis>
      </joint>
      <link name='knee_link'>
        <pose>1.6653314781029362e-17 2.9976021664879219e-16 0.7000000000000004 1.570796326794893 -1.5707963267948966 0</pose>
        <inertial>
          <pose>0 0 0 0 0 0</pose>
          <mass>1</mass>
          <inertia>
            <ixx>0.01</ixx>
            <ixy>0</ixy>
            <ixz>0</ixz>
            <iyy>0.01</iyy>
            <iyz>0</iyz>
            <izz>0.01</izz>
          </inertia>
        </inertial>
        <collision name='knee_link_collision'>
          <pose>-0.125 0 0 0 0 0</pose>
          <geometry>
            <box>
              <size>0.25 0.050000000000000003 0.02</size>
            </box>
          </geometry>
          <surface>
            <friction>
              <ode/>
            </friction>
            <bounce/>
            <contact/>
          </surface>
        </collision>
        <visual name='knee_link_visual'>
          <pose>-0.125 0 0 0 0 0</pose>
          <geometry>
            <box>
              <size>0.25 0.050000000000000003 0.02</size>
            </box>
          </geometry>
          <material>
            <diffuse>0 1 0 1</diffuse>
            <ambient>0 1 0 1</ambient>
          </material>
        </visual>
        <enable_wind>false</enable_wind>
      </link>
      <joint name='contact_joint' type='revolute'>
        <pose>0 0 0 0 0 0</pose>
        <parent>knee_link</parent>
        <child>foot_link</child>
        <axis>
          <xyz>0 0 1</xyz>
          <limit>
            <lower>0</lower>
            <upper>0</upper>
            <effort>1.0000000000000001e-05</effort>
            <velocity>1.0000000000000001e-05</velocity>
            <stiffness>100000000</stiffness>
            <dissipation>1</dissipation>
          </limit>
          <dynamics>
            <spring_reference>0</spring_reference>
            <spring_stiffness>0</spring_stiffness>
            <damping>0</damping>
            <friction>0</friction>
          </dynamics>
        </axis>
      </joint>
      <link name='foot_link'>
        <pose>-1.526557892673598e-16 7.4940054162198136e-16 0.45000000000000101 1.5707963267948892 -1.5707963267948966 0</pose>
        <inertial>
          <pose>0 0 0 0 0 0</pose>
          <mass>0.01</mass>
          <inertia>
            <ixx>0.01</ixx>
            <ixy>0</ixy>
            <ixz>0</ixz>
            <iyy>0.01</iyy>
            <iyz>0</iyz>
            <izz>0.01</izz>
          </inertia>
        </inertial>
        <collision name='foot_link_collision'>
          <pose>0 0 0 0 0 0</pose>
          <geometry>
            <sphere>
              <radius>0.050000000000000003</radius>
            </sphere>
          </geometry>
          <surface>
            <friction>
              <ode/>
            </friction>
            <bounce/>
            <contact/>
          </surface>
        </collision>
        <visual name='foot_link_visual'>
          <pose>0 0 0 0 0 0</pose>
          <geometry>
            <sphere>
              <radius>0.050000000000000003</radius>
            </sphere>
          </geometry>
        </visual>
        <sensor name='foot_contact' type='contact'>
          <always_on>true</always_on>
          <update_rate>100</update_rate>
          <contact>
            <collision>foot_link_collision</collision>
            <topic>/model/robot/sensors/contact</topic>
          </contact>
        </sensor>
        <enable_wind>false</enable_wind>
      </link>
      <plugin name='gz::sim::systems::JointStatePublisher' filename='gz-sim-joint-state-publisher-system'>
        <topic>model/robot/joint_states</topic>
        <joint_name>hip_joint</joint_name>
        <joint_name>knee_joint</joint_name>
      </plugin>
      <plugin name='gz::sim::systems::Contact' filename='gz-sim-contact-system'/>
      <plugin name='gz::sim::systems::JointPositionController' filename='gz-sim-joint-position-controller-system'>
        <joint_name>hip_joint</joint_name>
        <use_force_commands>true</use_force_commands>
        <sub_topic>joint/hip_joint/0/cmd_pos</sub_topic>
        <p_gain>5000.0</p_gain>
        <i_gain>1.0</i_gain>
        <d_gain>500.0</d_gain>
        <i_max>100</i_max>
        <i_min>-100</i_min>
        <cmd_max>100</cmd_max>
        <cmd_min>-100</cmd_min>
        <cmd_offset>0.0</cmd_offset>
      </plugin>
      <plugin name='gz::sim::systems::JointPositionController' filename='gz-sim-joint-position-controller-system'>
        <joint_name>knee_joint</joint_name>
        <use_force_commands>true</use_force_commands>
        <sub_topic>joint/knee_joint/0/cmd_pos</sub_topic>
        <p_gain>5000.0</p_gain>
        <i_gain>1.0</i_gain>
        <d_gain>500.0</d_gain>
        <i_max>100</i_max>
        <i_min>-100</i_min>
        <cmd_max>100</cmd_max>
        <cmd_min>-100</cmd_min>
        <cmd_offset>0.0</cmd_offset>
      </plugin>
      <frame name='imu_joint' attached_to='base_link'>
        <pose>0 0 0 0 0 0</pose>
      </frame>
      <frame name='imu_link' attached_to='imu_joint'>
        <pose>0 0 0 0 0 0</pose>
      </frame>
      <pose>0 0 -0.40000085536629026 0 0 0</pose>
      <static>false</static>
      <self_collide>false</self_collide>
    </model>
    <light name='sun' type='directional'>
      <pose>0 0 10 0 0 0</pose>
      <cast_shadows>true</cast_shadows>
      <intensity>1</intensity>
      <direction>-0.5 0.10000000000000001 -0.90000000000000002</direction>
      <diffuse>0.800000012 0.800000012 0.800000012 1</diffuse>
      <specular>0.200000003 0.200000003 0.200000003 1</specular>
      <attenuation>
        <range>1000</range>
        <linear>0.01</linear>
        <constant>0.90000000000000002</constant>
        <quadratic>0.001</quadratic>
      </attenuation>
      <spot>
        <inner_angle>0</inner_angle>
        <outer_angle>0</outer_angle>
        <falloff>0</falloff>
      </spot>
    </light>
  </world>
</sdf>
